Workbook
Name Direccion: 'Blok Presupuesto'!$F$8:$G$8
Name Listado: 'Blok Presupuesto'!$B$15:$H$32
Name Cliente: 'Blok Presupuesto'!$F$6:$G$6
Name Cliente: Presupuesto!$F$6:$G$6
Name Listado: Presupuesto!$B$15:$H$32
Name Direccion: Presupuesto!$F$8:$G$8
Name Fecha: 'Blok Presupuesto'!$F$4:$G$4
Name Fecha: Presupuesto!$F$4:$G$4

Sheet Nota
A1: =Presupuesto!A15 | B1: =IFERROR(VLOOKUP(Carga!B8,Precios!D:F,8,0), "") | C1: / | D1: =CONCATENATE(" ",C1," ",A1," ",B1) -> /
A2: =Presupuesto!A16 | B2: =IFERROR(VLOOKUP(Carga!B9,Precios!D:F,8,0), "") | C2: / | D2: =CONCATENATE(" / ",A2," ",B2) -> /
A3: =Presupuesto!A17 | B3: =IFERROR(VLOOKUP(Carga!B10,Precios!D:F,8,0), "") | C3: / | D3: =CONCATENATE(" / ",A3," ",B3) -> /
A4: =Presupuesto!A18 | B4: =IFERROR(VLOOKUP(Carga!B11,Precios!D:F,8,0), "") | C4: / | D4: =CONCATENATE(" / ",A4," ",B4) -> /
A5: =Presupuesto!A19 | B5: =IFERROR(VLOOKUP(Carga!B12,Precios!D:F,8,0), "") | C5: / | D5: =CONCATENATE(" / ",A5," ",B5) -> /
A6: =Presupuesto!A20 | B6: =IFERROR(VLOOKUP(Carga!B13,Precios!D:F,8,0), "") | C6: / | D6: =CONCATENATE(" / ",A6," ",B6) -> /
A7: =Presupuesto!A21 | B7: =IFERROR(VLOOKUP(Carga!B14,Precios!D:F,8,0), "") | C7: / | D7: =CONCATENATE(" / ",A7," ",B7) -> /
A8: =Presupuesto!A22 | B8: =IFERROR(VLOOKUP(Carga!B15,Precios!D:F,8,0), "") | C8: / | D8: =CONCATENATE(" / ",A8," ",B8) -> /
A9: =Presupuesto!A23 | B9: =IFERROR(VLOOKUP(Carga!B16,Precios!D:F,8,0), "") | C9: / | D9: =CONCATENATE(" / ",A9," ",B9) -> /
A10: =Presupuesto!A24 | B10: =IFERROR(VLOOKUP(Carga!B17,Precios!D:F,8,0), "") | C10: / | D10: =CONCATENATE(" / ",A10," ",B10) -> /
A11: =Presupuesto!A25 | B11: =IFERROR(VLOOKUP(Carga!B18,Precios!D:F,8,0), "") | C11: / | D11: =CONCATENATE(" / ",A11," ",B11) -> /
A12: =Presupuesto!A26 | B12: =IFERROR(VLOOKUP(Carga!B19,Precios!D:F,8,0), "") | C12: / | D12: =CONCATENATE(" / ",A12," ",B12) -> /
A13: =Presupuesto!A27 | B13: =IFERROR(VLOOKUP(Carga!B20,Precios!D:F,8,0), "") | C13: / | D13: =CONCATENATE(" / ",A13," ",B13) -> /
... A23: =Presupuesto!A37 | B23: =IFERROR(VLOOKUP(Carga!B30,Precios!D:F,8,0), "") | C23: / | D23: =CONCATENATE(" / ",A23," ",B23) -> /
E24: =CONCATENATE(D1:D23) -> / / / / / / / / / / / / / / / / / / / / / / /

Sheet Hoja8
A1: Concepto | B1: Cantidad | C1: Detalle ingresado | D1: precio unitario | E1: desc | F1: Total
A2: 46072 | B2: Villagrono Alfredus | C2: 3513559347 | D2: Enrique banchs 3281 los alamos
A3: Instalación a altura h<4mts con perfil C P/ BPC 100 a 300 | B3: 1 | C3: 43400 | D3: 43400 | F3: TOTAL
A4: Instalación a altura h<4mts con perfil C P/ BPC 100 a 300 | B4: 1 | C4: 43400 | D4: 43400 | F4: 292800
A5: Instalación a altura h<4mts con perfil C P/ BPC 100 a 300 | B5: 1 | C5: 43400 | D5: 43400 | F5: 292800
A6: Instalación a altura h<4mts con perfil C P/ BPC 100 a 300 | B6: 1 | C6: 43400 | D6: 43400 | F6: 292800
A7: Instalación a altura h<4mts con perfil C P/ BPC 100 a 300 | B7: 1 | C7: 43400 | D7: 43400 | F7: -180000
A8: Instalación a altura h<4mts con perfil C P/ BPC 100 a 300 | B8: 1 | C8: 43400 | D8: 2.387e+16 | F8: -180000
A9: Certificacion de vivienda o local comercial (hasta 20bocas) no incluye adecuacion de la instalacion | B9: -2 | D9: 180000 | E9: 0 | F9: -360000
A10: Certificacion de vivienda o local comercial (hasta 20bocas) no incluye adecuacion de la instalacion | B10: -2 | D10: 180000 | E10: 0 | F10: -360000
A11: Certificacion de vivienda o local comercial (hasta 20bocas) no incluye adecuacion de la instalacion | B11: -2 | D11: 180000 | E11: 0 | F11: -360000
A12: Certificacion de vivienda o local comercial (hasta 20bocas) no incluye adecuacion de la instalacion | B12: -2 | D12: 180000 | E12: 0 | F12: -360000
A13: Certificacion de vivienda o local comercial (hasta 20bocas) no incluye adecuacion de la instalacion | B13: -2 | D13: 180000 | E13: 0 | F13: -360000
A14: Certificacion de vivienda o local comercial (hasta 20bocas) no incluye adecuacion de la instalacion | B14: -2 | D14: 180000 | E14: 0 | F14: -360000
A15: Certificacion de vivienda o local comercial (hasta 20bocas) no incluye adecuacion de la instalacion | B15: -2 | D15: 180000 | E15: 0 | F15: -360000
A16: Certificacion de vivienda o local comercial (hasta 20bocas) no incluye adecuacion de la instalacion | B16: -2 | D16: 180000 | E16: 0 | F16: -360000
A17: Certificacion de vivienda o local comercial (hasta 20bocas) no incluye adecuacion de la instalacion | B17: -2 | D17: 180000 | E17: 0 | F17: -360000
A18: Certificacion de vivienda o local comercial (hasta 20bocas) no incluye adecuacion de la instalacion | B18: -2 | D18: 180000 | E18: 0 | F18: -360000
A19: Certificacion de vivienda o local comercial (hasta 20bocas) no incluye adecuacion de la instalacion | B19: -2 | D19: 180000 | E19: 0 | F19: -360000
A20: Certificacion de vivienda o local comercial (hasta 20bocas) no incluye adecuacion de la instalacion | B20: -2 | D20: 180000 | E20: 0 | F20: -360000
... A36: Certificacion de vivienda o local comercial (hasta 20bocas) no incluye adecuacion de la instalacion | B36: -2 | D36: 180000 | E36: 0 | F36: -360000
A37: Certificacion de vivienda o local comercial (hasta 20bocas) no incluye adecuacion de la instalacion | B37: -2 | C37: Jkota | D37: 180000 | E37: 0 | F37: -360000

Sheet Clientes
A1: =IFERROR(__xludf.DUMMYFUNCTION("IMPORTRANGE(""https://docs.google.com/spreadsheets/d/1aPynYCYBaEafPC4rqTulMOzPg_guy_NLzZHOzvFJwyw/edit?usp=drivesdk"", ""Respuestas de formulario 1!A1:H150"")"),"Marca temporal") -> Marca temporal | B1: =IFERROR(__xludf.DUMMYFUNCTION("""COMPUTED_VALUE"""),"Apellido y Nombre") -> Apellido y Nombre | C1: =IFERROR(__xludf.DUMMYFUNCTION("""COMPUTED_VALUE"""),"Teléfono") -> Teléfono | D1: =IFERROR(__xludf.DUMMYFUNCTION("""COMPUTED_VALUE"""),"Dirección") -> Dirección | E1: =IFERROR(__xludf.DUMMYFUNCTION("""COMPUTED_VALUE"""),"Observaciones ") -> Observaciones
A2: =IFERROR(__xludf.DUMMYFUNCTION("""COMPUTED_VALUE"""),46065.8989693287) -> 46065.899 | B2: =IFERROR(__xludf.DUMMYFUNCTION("""COMPUTED_VALUE"""),"Villagrono Alfredus") -> Villagrono Alfredus | C2: =IFERROR(__xludf.DUMMYFUNCTION("""COMPUTED_VALUE"""),3.513559347E9) -> 3513559347 | D2: =IFERROR(__xludf.DUMMYFUNCTION("""COMPUTED_VALUE"""),"Enrique banchs 3281 los alamos") -> Enrique banchs 3281 los alamos | E2: =IFERROR(__xludf.DUMMYFUNCTION("""COMPUTED_VALUE"""),"Alfredus Alfredus") -> Alfredus Alfredus
A3: =IFERROR(__xludf.DUMMYFUNCTION("""COMPUTED_VALUE"""),46065.90200585648) -> 46065.902 | B3: =IFERROR(__xludf.DUMMYFUNCTION("""COMPUTED_VALUE"""),"Federico Matisaleno") -> Federico Matisaleno | C3: =IFERROR(__xludf.DUMMYFUNCTION("""COMPUTED_VALUE"""),3.518469723E9) -> 3518469723 | D3: =IFERROR(__xludf.DUMMYFUNCTION("""COMPUTED_VALUE"""),"Domingo Zipoli 542 Cordoba ") -> Domingo Zipoli 542 Cordoba
A4: =IFERROR(__xludf.DUMMYFUNCTION("""COMPUTED_VALUE"""),46065.914829490735) -> 46065.915 | B4: =IFERROR(__xludf.DUMMYFUNCTION("""COMPUTED_VALUE"""),"Lucianote Pabarotiitii") -> Lucianote Pabarotiitii | C4: =IFERROR(__xludf.DUMMYFUNCTION("""COMPUTED_VALUE"""),3.513559347E9) -> 3513559347 | D4: =IFERROR(__xludf.DUMMYFUNCTION("""COMPUTED_VALUE"""),"Domingo Funesialo 54612 Barro Campañaioni") -> Domingo Funesialo 54612 Barro Campañaioni
A5: =IFERROR(__xludf.DUMMYFUNCTION("""COMPUTED_VALUE"""),46065.91937481481) -> 46065.919 | B5: =IFERROR(__xludf.DUMMYFUNCTION("""COMPUTED_VALUE"""),"Gorgoto") -> Gorgoto | C5: =IFERROR(__xludf.DUMMYFUNCTION("""COMPUTED_VALUE"""),3.513559347E9) -> 3513559347 | D5: =IFERROR(__xludf.DUMMYFUNCTION("""COMPUTED_VALUE"""),"Jsjsjjd bsjsj 51518 vdbjdj") -> Jsjsjjd bsjsj 51518 vdbjdj
A6: =IFERROR(__xludf.DUMMYFUNCTION("""COMPUTED_VALUE"""),46067.909977083335) -> 46067.91 | B6: =IFERROR(__xludf.DUMMYFUNCTION("""COMPUTED_VALUE"""),"Lolito Supertino") -> Lolito Supertino | C6: =IFERROR(__xludf.DUMMYFUNCTION("""COMPUTED_VALUE"""),3.513559347E9) -> 3513559347 | D6: =IFERROR(__xludf.DUMMYFUNCTION("""COMPUTED_VALUE"""),"Bulevares de san juan 3456 Barrio Lopes de vega") -> Bulevares de san juan 3456 Barrio Lopes de vega
A7: =IFERROR(__xludf.DUMMYFUNCTION("""COMPUTED_VALUE"""),46068.722087222224) -> 46068.722 | B7: =IFERROR(__xludf.DUMMYFUNCTION("""COMPUTED_VALUE"""),"Federico Orellano") -> Federico Orellano | C7: =IFERROR(__xludf.DUMMYFUNCTION("""COMPUTED_VALUE"""),3.513559347E9) -> 3513559347 | D7: =IFERROR(__xludf.DUMMYFUNCTION("""COMPUTED_VALUE"""),"Prueba 1234 Bro Prueba 1 cp 4321") -> Prueba 1234 Bro Prueba 1 cp 4321 | E7: =IFERROR(__xludf.DUMMYFUNCTION("""COMPUTED_VALUE"""),"Ywwjye") -> Ywwjye
A8: =IFERROR(__xludf.DUMMYFUNCTION("""COMPUTED_VALUE"""),46068.72213230324) -> 46068.722 | B8: =IFERROR(__xludf.DUMMYFUNCTION("""COMPUTED_VALUE"""),"Federico Orellano") -> Federico Orellano | C8: =IFERROR(__xludf.DUMMYFUNCTION("""COMPUTED_VALUE"""),3.513559347E9) -> 3513559347 | D8: =IFERROR(__xludf.DUMMYFUNCTION("""COMPUTED_VALUE"""),"Prueba 1234 Bro Prueba 1 cp 4321") -> Prueba 1234 Bro Prueba 1 cp 4321 | E8: =IFERROR(__xludf.DUMMYFUNCTION("""COMPUTED_VALUE"""),"eiie") -> eiie
A9: =IFERROR(__xludf.DUMMYFUNCTION("""COMPUTED_VALUE"""),46068.722922430556) -> 46068.723 | B9: =IFERROR(__xludf.DUMMYFUNCTION("""COMPUTED_VALUE"""),"Juanito") -> Juanito | C9: =IFERROR(__xludf.DUMMYFUNCTION("""COMPUTED_VALUE"""),12345.0) -> 12345 | D9: =IFERROR(__xludf.DUMMYFUNCTION("""COMPUTED_VALUE"""),"0987654321") -> 0987654321 | E9: =IFERROR(__xludf.DUMMYFUNCTION("""COMPUTED_VALUE"""),"jjjt") -> jjjt
A10: =IFERROR(__xludf.DUMMYFUNCTION("""COMPUTED_VALUE"""),46068.726037500004) -> 46068.726 | B10: =IFERROR(__xludf.DUMMYFUNCTION("""COMPUTED_VALUE"""),"Nieva Prueba") -> Nieva Prueba | C10: =IFERROR(__xludf.DUMMYFUNCTION("""COMPUTED_VALUE"""),3.513559347E9) -> 3513559347 | D10: =IFERROR(__xludf.DUMMYFUNCTION("""COMPUTED_VALUE"""),"Dirección de prueba 1") -> Dirección de prueba 1
A11: =IFERROR(__xludf.DUMMYFUNCTION("""COMPUTED_VALUE"""),46068.73903166667) -> 46068.739 | B11: =IFERROR(__xludf.DUMMYFUNCTION("""COMPUTED_VALUE"""),"Pepito monje") -> Pepito monje | C11: =IFERROR(__xludf.DUMMYFUNCTION("""COMPUTED_VALUE"""),3.513559347E9) -> 3513559347 | D11: =IFERROR(__xludf.DUMMYFUNCTION("""COMPUTED_VALUE"""),"Guntanamera 1020") -> Guntanamera 1020 | E11: =IFERROR(__xludf.DUMMYFUNCTION("""COMPUTED_VALUE"""),"rujrr") -> rujrr
A12: =IFERROR(__xludf.DUMMYFUNCTION("""COMPUTED_VALUE"""),46069.04093928241) -> 46069.041 | B12: =IFERROR(__xludf.DUMMYFUNCTION("""COMPUTED_VALUE"""),"Villagra Sergio") -> Villagra Sergio | C12: =IFERROR(__xludf.DUMMYFUNCTION("""COMPUTED_VALUE"""),3.513559347E9) -> 3513559347 | D12: =IFERROR(__xludf.DUMMYFUNCTION("""COMPUTED_VALUE"""),"Domingo Zipoli 4567 Barrio Alberdi CP 5002") -> Domingo Zipoli 4567 Barrio Alberdi CP 5002 | E12: =IFERROR(__xludf.DUMMYFUNCTION("""COMPUTED_VALUE"""),"eiie") -> eiie
A13: =IFERROR(__xludf.DUMMYFUNCTION("""COMPUTED_VALUE"""),46069.072799166664) -> 46069.073 | B13: =IFERROR(__xludf.DUMMYFUNCTION("""COMPUTED_VALUE"""),"Preuga corte de luz") -> Preuga corte de luz | C13: =IFERROR(__xludf.DUMMYFUNCTION("""COMPUTED_VALUE"""),3.513559347E9) -> 3513559347 | D13: =IFERROR(__xludf.DUMMYFUNCTION("""COMPUTED_VALUE"""),"Gregorio correa 1837 cp Kdkdk barrio") -> Gregorio correa 1837 cp Kdkdk barrio | E13: =IFERROR(__xludf.DUMMYFUNCTION("""COMPUTED_VALUE"""),"rjjrjr") -> rjjrjr
A14: =IFERROR(__xludf.DUMMYFUNCTION("""COMPUTED_VALUE"""),46069.79447824074) -> 46069.794 | B14: =IFERROR(__xludf.DUMMYFUNCTION("""COMPUTED_VALUE"""),"Orueba123456") -> Orueba123456 | C14: =IFERROR(__xludf.DUMMYFUNCTION("""COMPUTED_VALUE"""),3.513559347E9) -> 3513559347 | D14: =IFERROR(__xludf.DUMMYFUNCTION("""COMPUTED_VALUE"""),"Enrique banchs 3281 los alamos") -> Enrique banchs 3281 los alamos | E14: =IFERROR(__xludf.DUMMYFUNCTION("""COMPUTED_VALUE"""),"iriri") -> iriri
A15: =IFERROR(__xludf.DUMMYFUNCTION("""COMPUTED_VALUE"""),46069.79786993055) -> 46069.798 | B15: =IFERROR(__xludf.DUMMYFUNCTION("""COMPUTED_VALUE"""),"Prueba numero 2") -> Prueba numero 2 | C15: =IFERROR(__xludf.DUMMYFUNCTION("""COMPUTED_VALUE"""),3.513559347E9) -> 3513559347 | D15: =IFERROR(__xludf.DUMMYFUNCTION("""COMPUTED_VALUE"""),"https://maps.app.goo.gl/xuNo6YtDjecjWtoJ7") -> https://maps.app.goo.gl/xuNo6YtDjecjWtoJ7 | E15: =IFERROR(__xludf.DUMMYFUNCTION("""COMPUTED_VALUE"""),"ggg") -> ggg
A16: =IFERROR(__xludf.DUMMYFUNCTION("""COMPUTED_VALUE"""),46070.066752638886) -> 46070.067 | B16: =IFERROR(__xludf.DUMMYFUNCTION("""COMPUTED_VALUE"""),"Nuevo Nuevito peresoso") -> Nuevo Nuevito peresoso | C16: =IFERROR(__xludf.DUMMYFUNCTION("""COMPUTED_VALUE"""),3.513559346E9) -> 3513559346 | D16: =IFERROR(__xludf.DUMMYFUNCTION("""COMPUTED_VALUE"""),"Domingo Zipoli 2368 alberdi cordoba") -> Domingo Zipoli 2368 alberdi cordoba
A17: =IFERROR(__xludf.DUMMYFUNCTION("""COMPUTED_VALUE"""),46070.47383278935) -> 46070.474 | B17: =IFERROR(__xludf.DUMMYFUNCTION("""COMPUTED_VALUE"""),"Ultima carga") -> Ultima carga | C17: =IFERROR(__xludf.DUMMYFUNCTION("""COMPUTED_VALUE"""),3.513559347E9) -> 3513559347 | D17: =IFERROR(__xludf.DUMMYFUNCTION("""COMPUTED_VALUE"""),"Ultima carga de prueba") -> Ultima carga de prueba
A18: =IFERROR(__xludf.DUMMYFUNCTION("""COMPUTED_VALUE"""),46070.68906409723) -> 46070.689 | B18: =IFERROR(__xludf.DUMMYFUNCTION("""COMPUTED_VALUE"""),"Gorgito") -> Gorgito | C18: =IFERROR(__xludf.DUMMYFUNCTION("""COMPUTED_VALUE"""),3.513589347E9) -> 3513589347 | D18: =IFERROR(__xludf.DUMMYFUNCTION("""COMPUTED_VALUE"""),"Nieva dirección ") -> Nieva dirección
A19: =IFERROR(__xludf.DUMMYFUNCTION("""COMPUTED_VALUE"""),46070.694844212965) -> 46070.695 | B19: =IFERROR(__xludf.DUMMYFUNCTION("""COMPUTED_VALUE"""),"Gonzalote") -> Gonzalote | C19: =IFERROR(__xludf.DUMMYFUNCTION("""COMPUTED_VALUE"""),3.513559347E9) -> 3513559347 | D19: =IFERROR(__xludf.DUMMYFUNCTION("""COMPUTED_VALUE"""),"Domingo zipoli 345 https://maps.app.goo.gl/vXvuksTmu9fyES1f7 ") -> Domingo zipoli 345 https://maps.app.goo.gl/vXvuksTmu9fyES1f7
A20: =IFERROR(__xludf.DUMMYFUNCTION("""COMPUTED_VALUE"""),46070.73501456018) -> 46070.735 | B20: =IFERROR(__xludf.DUMMYFUNCTION("""COMPUTED_VALUE"""),"Anita Machado") -> Anita Machado | C20: =IFERROR(__xludf.DUMMYFUNCTION("""COMPUTED_VALUE"""),3.513090975E9) -> 3513090975 | D20: =IFERROR(__xludf.DUMMYFUNCTION("""COMPUTED_VALUE"""),"Ruta 20 Ruta 20 deliverys, Fructuoso Rivera 1063, Fructuoso Rivera 1000, X5000 Córdoba") -> Ruta 20 Ruta 20 deliverys, Fructuoso Rivera 1063, Fructuoso Rivera 1000, X5000 Córdoba | E20: =IFERROR(__xludf.DUMMYFUNCTION("""COMPUTED_VALUE"""),"eia") -> eia
A21: =IFERROR(__xludf.DUMMYFUNCTION("""COMPUTED_VALUE"""),46070.990546932866) -> 46070.991 | B21: =IFERROR(__xludf.DUMMYFUNCTION("""COMPUTED_VALUE"""),"Prueba masemyerchef") -> Prueba masemyerchef | C21: =IFERROR(__xludf.DUMMYFUNCTION("""COMPUTED_VALUE"""),3.513559345E9) -> 3513559345 | D21: =IFERROR(__xludf.DUMMYFUNCTION("""COMPUTED_VALUE"""),"San Fernando 3245, Los Álamos, Córdoba, Provincia de Córdoba") -> San Fernando 3245, Los Álamos, Córdoba, Provincia de Córdoba
A22: =IFERROR(__xludf.DUMMYFUNCTION("""COMPUTED_VALUE"""),46071.01636951389) -> 46071.016 | B22: =IFERROR(__xludf.DUMMYFUNCTION("""COMPUTED_VALUE"""),"Villagra Villagra") -> Villagra Villagra | C22: =IFERROR(__xludf.DUMMYFUNCTION("""COMPUTED_VALUE"""),3.513559347E9) -> 3513559347 | D22: =IFERROR(__xludf.DUMMYFUNCTION("""COMPUTED_VALUE"""),"Av. Leandro N. Alem 3900, Córdoba, Provincia de Córdoba") -> Av. Leandro N. Alem 3900, Córdoba, Provincia de Córdoba | E22: =IFERROR(__xludf.DUMMYFUNCTION("""COMPUTED_VALUE"""),"Pruebillacitass") -> Pruebillacitass
A23: =IFERROR(__xludf.DUMMYFUNCTION("""COMPUTED_VALUE"""),46072.167987719906) -> 46072.168 | B23: =IFERROR(__xludf.DUMMYFUNCTION("""COMPUTED_VALUE"""),"Billa") -> Billa | C23: =IFERROR(__xludf.DUMMYFUNCTION("""COMPUTED_VALUE"""),3.513559347E9) -> 3513559347 | D23: =IFERROR(__xludf.DUMMYFUNCTION("""COMPUTED_VALUE"""),"Hshajs") -> Hshajs
A24: =IFERROR(__xludf.DUMMYFUNCTION("""COMPUTED_VALUE"""),46072.17262324074) -> 46072.173 | B24: =IFERROR(__xludf.DUMMYFUNCTION("""COMPUTED_VALUE"""),"Kkkkkkkkkkk") -> Kkkkkkkkkkk | C24: =IFERROR(__xludf.DUMMYFUNCTION("""COMPUTED_VALUE"""),3.513559347E9) -> 3513559347 | D24: =IFERROR(__xludf.DUMMYFUNCTION("""COMPUTED_VALUE"""),"Kkkkkkkk") -> Kkkkkkkk
A25: =IFERROR(__xludf.DUMMYFUNCTION("""COMPUTED_VALUE"""),46072.178416863426) -> 46072.178 | B25: =IFERROR(__xludf.DUMMYFUNCTION("""COMPUTED_VALUE"""),"Dies numeros") -> Dies numeros | C25: =IFERROR(__xludf.DUMMYFUNCTION("""COMPUTED_VALUE"""),1.213615555E9) -> 1213615555 | D25: =IFERROR(__xludf.DUMMYFUNCTION("""COMPUTED_VALUE"""),"Gshsh") -> Gshsh
A26: =IFERROR(__xludf.DUMMYFUNCTION("""COMPUTED_VALUE"""),46072.17998886574) -> 46072.18 | B26: =IFERROR(__xludf.DUMMYFUNCTION("""COMPUTED_VALUE"""),"Otraprueba") -> Otraprueba | C26: =IFERROR(__xludf.DUMMYFUNCTION("""COMPUTED_VALUE"""),1.23456789E9) -> 1234567890 | D26: =IFERROR(__xludf.DUMMYFUNCTION("""COMPUTED_VALUE"""),"Otra prueba") -> Otra prueba | E26: =IFERROR(__xludf.DUMMYFUNCTION("""COMPUTED_VALUE"""),"gg") -> gg
A27: =IFERROR(__xludf.DUMMYFUNCTION("""COMPUTED_VALUE"""),46072.195380798614) -> 46072.195 | B27: =IFERROR(__xludf.DUMMYFUNCTION("""COMPUTED_VALUE"""),"Ghhhhh") -> Ghhhhh | C27: =IFERROR(__xludf.DUMMYFUNCTION("""COMPUTED_VALUE"""),5.213655566E9) -> 5213655566 | D27: =IFERROR(__xludf.DUMMYFUNCTION("""COMPUTED_VALUE"""),"Ghh") -> Ghh
A28: =IFERROR(__xludf.DUMMYFUNCTION("""COMPUTED_VALUE"""),46072.19978998843) -> 46072.2 | B28: =IFERROR(__xludf.DUMMYFUNCTION("""COMPUTED_VALUE"""),"Otra pruebexicixixixllla mas ") -> Otra pruebexicixixixllla mas | C28: =IFERROR(__xludf.DUMMYFUNCTION("""COMPUTED_VALUE"""),3.512364676E9) -> 3512364676 | D28: =IFERROR(__xludf.DUMMYFUNCTION("""COMPUTED_VALUE"""),"Ysysy") -> Ysysy
A29: =IFERROR(__xludf.DUMMYFUNCTION("""COMPUTED_VALUE"""),46072.70643569445) -> 46072.706 | B29: =IFERROR(__xludf.DUMMYFUNCTION("""COMPUTED_VALUE"""),"Villagra Sergio Adrian") -> Villagra Sergio Adrian | C29: =IFERROR(__xludf.DUMMYFUNCTION("""COMPUTED_VALUE"""),3.513559347E9) -> 3513559347 | D29: =IFERROR(__xludf.DUMMYFUNCTION("""COMPUTED_VALUE"""),"Enrique Banchs 3281, X5012 Córdoba") -> Enrique Banchs 3281, X5012 Córdoba | E29: =IFERROR(__xludf.DUMMYFUNCTION("""COMPUTED_VALUE"""),"El maximo 😎😎😎😎") -> El maximo 😎😎😎😎
A30: =IFERROR(__xludf.DUMMYFUNCTION("""COMPUTED_VALUE"""),46073.738713425926) -> 46073.739 | B30: =IFERROR(__xludf.DUMMYFUNCTION("""COMPUTED_VALUE"""),"Sergio Villagra MTX") -> Sergio Villagra MTX | C30: =IFERROR(__xludf.DUMMYFUNCTION("""COMPUTED_VALUE"""),3.513559347E9) -> 3513559347 | D30: =IFERROR(__xludf.DUMMYFUNCTION("""COMPUTED_VALUE"""),"Octavio Pinto 3457, Córdoba, Provincia de Córdoba") -> Octavio Pinto 3457, Córdoba, Provincia de Córdoba | E30: =IFERROR(__xludf.DUMMYFUNCTION("""COMPUTED_VALUE"""),"Aqui se deben de colocar todas las observaciones.") -> Aqui se deben de colocar todas las observaciones.
A31: =IFERROR(__xludf.DUMMYFUNCTION("""COMPUTED_VALUE"""),46074.17716305556) -> 46074.177 | B31: =IFERROR(__xludf.DUMMYFUNCTION("""COMPUTED_VALUE"""),"Jeronimo ") -> Jeronimo | C31: =IFERROR(__xludf.DUMMYFUNCTION("""COMPUTED_VALUE"""),3.513559347E9) -> 3513559347 | D31: =IFERROR(__xludf.DUMMYFUNCTION("""COMPUTED_VALUE"""),"Jerónimo Luis de Cabrera 345, X5000GVG X5000GVG, Córdoba") -> Jerónimo Luis de Cabrera 345, X5000GVG X5000GVG, Córdoba | E31: =IFERROR(__xludf.DUMMYFUNCTION("""COMPUTED_VALUE"""),"Modificaciones de datos ") -> Modificaciones de datos
A32: =IFERROR(__xludf.DUMMYFUNCTION("""COMPUTED_VALUE"""),46074.38879064815) -> 46074.389 | B32: =IFERROR(__xludf.DUMMYFUNCTION("""COMPUTED_VALUE"""),"Pepito Mpnje") -> Pepito Mpnje | C32: =IFERROR(__xludf.DUMMYFUNCTION("""COMPUTED_VALUE"""),3.513559347E9) -> 3513559347 | D32: =IFERROR(__xludf.DUMMYFUNCTION("""COMPUTED_VALUE"""),"La Rioja 368, X5022FRH Córdoba") -> La Rioja 368, X5022FRH Córdoba | E32: =IFERROR(__xludf.DUMMYFUNCTION("""COMPUTED_VALUE"""),"Cliente conflictivo, avisado por otros electricistas ") -> Cliente conflictivo, avisado por otros electricistas
A33: =IFERROR(__xludf.DUMMYFUNCTION("""COMPUTED_VALUE"""),46082.04411354166) -> 46082.044 | B33: =IFERROR(__xludf.DUMMYFUNCTION("""COMPUTED_VALUE"""),"Leonel Suarez") -> Leonel Suarez | C33: =IFERROR(__xludf.DUMMYFUNCTION("""COMPUTED_VALUE"""),3.516595494E9) -> 3516595494 | D33: =IFERROR(__xludf.DUMMYFUNCTION("""COMPUTED_VALUE"""),"Enrique Banchs 3281, X5012 Córdoba") -> Enrique Banchs 3281, X5012 Córdoba | E33: =IFERROR(__xludf.DUMMYFUNCTION("""COMPUTED_VALUE"""),"Cargamos cambios") -> Cargamos cambios
A34: =IFERROR(__xludf.DUMMYFUNCTION("""COMPUTED_VALUE"""),46087.56516125) -> 46087.565 | B34: =IFERROR(__xludf.DUMMYFUNCTION("""COMPUTED_VALUE"""),"Facundo Suarez Materiales Eléctricos") -> Facundo Suarez Materiales Eléctricos | C34: =IFERROR(__xludf.DUMMYFUNCTION("""COMPUTED_VALUE"""),3.517693218E9) -> 3517693218 | D34: =IFERROR(__xludf.DUMMYFUNCTION("""COMPUTED_VALUE"""),"Lino Eneas Spilimbergo 5000, X5001 Córdoba") -> Lino Eneas Spilimbergo 5000, X5001 Córdoba | E34: =IFERROR(__xludf.DUMMYFUNCTION("""COMPUTED_VALUE"""),"www.sgselectricidad@gmail.com SGS Materiales Eléctricos e Iluminación") -> www.sgselectricidad@gmail.com SGS Materiales Eléctricos e Iluminación
A35: =IFERROR(__xludf.DUMMYFUNCTION("""COMPUTED_VALUE"""),46089.7175712037) -> 46089.718 | B35: =IFERROR(__xludf.DUMMYFUNCTION("""COMPUTED_VALUE"""),"Lara Suárez ") -> Lara Suárez | C35: =IFERROR(__xludf.DUMMYFUNCTION("""COMPUTED_VALUE"""),3.513568653E9) -> 3513568653 | D35: =IFERROR(__xludf.DUMMYFUNCTION("""COMPUTED_VALUE"""),"San Francisco 1231, X5012CSE Córdoba") -> San Francisco 1231, X5012CSE Córdoba | E35: =IFERROR(__xludf.DUMMYFUNCTION("""COMPUTED_VALUE"""),"Chussasera !!! 😆") -> Chussasera !!! 😆
A36: =IFERROR(__xludf.DUMMYFUNCTION("""COMPUTED_VALUE"""),46089.88928736111) -> 46089.889 | B36: =IFERROR(__xludf.DUMMYFUNCTION("""COMPUTED_VALUE"""),"Sergio Villagra Prueba ") -> Sergio Villagra Prueba | C36: =IFERROR(__xludf.DUMMYFUNCTION("""COMPUTED_VALUE"""),3.513559347E9) -> 3513559347 | D36: =IFERROR(__xludf.DUMMYFUNCTION("""COMPUTED_VALUE"""),"Enrique Banchs 3281, X5012 Córdoba") -> Enrique Banchs 3281, X5012 Córdoba | E36: =IFERROR(__xludf.DUMMYFUNCTION("""COMPUTED_VALUE"""),"Edicion nueva") -> Edicion nueva
A37: =IFERROR(__xludf.DUMMYFUNCTION("""COMPUTED_VALUE"""),46122.10008899306) -> 46122.1 | B37: =IFERROR(__xludf.DUMMYFUNCTION("""COMPUTED_VALUE"""),"Villagra Sergio ") -> Villagra Sergio | C37: =IFERROR(__xludf.DUMMYFUNCTION("""COMPUTED_VALUE"""),3.513559347E9) -> 3513559347 | D37: =IFERROR(__xludf.DUMMYFUNCTION("""COMPUTED_VALUE"""),"Enrique Banchs 3281, X5012 Córdoba") -> Enrique Banchs 3281, X5012 Córdoba
A38: =IFERROR(__xludf.DUMMYFUNCTION("""COMPUTED_VALUE"""),46122.379640150466) -> 46122.38 | B38: =IFERROR(__xludf.DUMMYFUNCTION("""COMPUTED_VALUE"""),"VILLAGRATAA") -> VILLAGRATAA | C38: =IFERROR(__xludf.DUMMYFUNCTION("""COMPUTED_VALUE"""),3.513559347E9) -> 3513559347 | D38: =IFERROR(__xludf.DUMMYFUNCTION("""COMPUTED_VALUE"""),"Domingo Zípoli 267, X5000 Córdoba") -> Domingo Zípoli 267, X5000 Córdoba | E38: =IFERROR(__xludf.DUMMYFUNCTION("""COMPUTED_VALUE"""),"CLIENTE: VILLAGRATAA TELÉFONO: 3513559347 DIRECCIÓN: Domingo Zípoli 267, X5000 Córdoba NOTAS: ") -> CLIENTE: VILLAGRATAA TELÉFONO: 3513559347 DIRECCIÓN: Domingo Zípoli 267, X5000 Córdoba NOTAS:
A39: =IFERROR(__xludf.DUMMYFUNCTION("""COMPUTED_VALUE"""),46122.74433998842) -> 46122.744 | B39: =IFERROR(__xludf.DUMMYFUNCTION("""COMPUTED_VALUE"""),"Hshsh") -> Hshsh | C39: =IFERROR(__xludf.DUMMYFUNCTION("""COMPUTED_VALUE"""),1.23456789E9) -> 1234567890 | D39: =IFERROR(__xludf.DUMMYFUNCTION("""COMPUTED_VALUE"""),"Octavio Pinto 3247, X5000 Córdoba") -> Octavio Pinto 3247, X5000 Córdoba | E39: =IFERROR(__xludf.DUMMYFUNCTION("""COMPUTED_VALUE"""),"Teléfono agregado") -> Teléfono agregado
A40: =IFERROR(__xludf.DUMMYFUNCTION("""COMPUTED_VALUE"""),46122.744394629626) -> 46122.744 | B40: =IFERROR(__xludf.DUMMYFUNCTION("""COMPUTED_VALUE"""),"Hshsh") -> Hshsh | C40: =IFERROR(__xludf.DUMMYFUNCTION("""COMPUTED_VALUE"""),"0123456789") -> 0123456789 | D40: =IFERROR(__xludf.DUMMYFUNCTION("""COMPUTED_VALUE"""),"Octavio Pinto 3247, X5000 Córdoba") -> Octavio Pinto 3247, X5000 Córdoba
...

Sheet Carga
A2: Fecha | B2: 46067
A3: Nombre | B3: Pepito monje
A4: Dirección | B4: =VLOOKUP(B3,Clientes!B2:D200,3,0) -> Guntanamera 1020
A6: Tema | B6: Concepto | C6: descuento | F6: Cantidad | G6: Valor | I6: sub | K6: descuentos en % | M6: concatenado
C7: porcentaje | D7: % | E7: detalle
A8: DOCUMENTACIÓN, CERTIFICACIÓN Y SERVICIO DE MEDICIÓN | B8: Visita de inspeccion | F8: 1 | G8: =IFERROR(VLOOKUP(B8,Precios!D:E,2,0), "") | I8: =IF(G8*F8=0, "",G8*F8) | K8: =(SUM($I$8:$I$33)*C8)/-100 -> 0 | M8: =IF(I8+K8=0, "",I8+K8)
A9: DESCUENTO | B9: Visita de Inspección - Bonificación | F9: 1 | G9: =IFERROR(VLOOKUP(B9,Precios!D:E,2,0), "") | I9: =IF(G9*F9=0, "",G9*F9) | K9: =(SUM($I$8:$I$33)*C9)/-100 -> 0 | M9: =IF(I9+K9=0, "",I9+K9)
A10: CABLEADOS EN CAÑERÍAS | B10: Recableado (incluye sacar artef, llaves y colocar nueva instalación) por Boca | F10: 1 | G10: =IFERROR(VLOOKUP(B10,Precios!D:E,2,0), "") -> 56500 | I10: =IF(G10*F10=0, "",G10*F10) -> 56500 | K10: =(SUM($I$8:$I$33)*C10)/-100 -> 0 | M10: =IF(I10+K10=0, "",I10+K10) -> 56500
A11: DESCUENTO | B11: Otros Descuentos | C11: 45 | D11: % | G11: =IFERROR(VLOOKUP(B11,Precios!D:E,2,0), "") | I11: =IF(G11*F11=0, "",G11*F11) | K11: =(SUM($I$8:$I$33)*C11)/-100 -> -155475 | M11: =IF(I11+K11=0, "",I11+K11) -> -155475
G12: =IFERROR(VLOOKUP(B12,Precios!D:E,2,0), "") | I12: =IF(G12*F12=0, "",G12*F12) | K12: =(SUM($I$8:$I$33)*C12)/-100 -> 0 | M12: =IF(I12+K12=0, "",I12+K12)
G13: =IFERROR(VLOOKUP(B13,Precios!D:E,2,0), "") | I13: =IF(G13*F13=0, "",G13*F13) | K13: =(SUM($I$8:$I$33)*C13)/-100 -> 0 | M13: =IF(I13+K13=0, "",I13+K13)
G14: =IFERROR(VLOOKUP(B14,Precios!D:E,2,0), "") | I14: =IF(G14*F14=0, "",G14*F14) | K14: =(SUM($I$8:$I$33)*C14)/-100 -> 0 | M14: =IF(I14+K14=0, "",I14+K14)
G15: =IFERROR(VLOOKUP(B15,Precios!D:E,2,0), "") | I15: =IF(G15*F15=0, "",G15*F15) | K15: =(SUM($I$8:$I$33)*C15)/-100 -> 0 | M15: =IF(I15+K15=0, "",I15+K15)
G16: =IFERROR(VLOOKUP(B16,Precios!D:E,2,0), "") | I16: =IF(G16*F16=0, "",G16*F16) | K16: =(SUM($I$8:$I$33)*C16)/-100 -> 0 | M16: =IF(I16+K16=0, "",I16+K16)
G17: =IFERROR(VLOOKUP(B17,Precios!D:E,2,0), "") | I17: =IF(G17*F17=0, "",G17*F17) | K17: =(SUM($I$8:$I$33)*C17)/-100 -> 0 | M17: =IF(I17+K17=0, "",I17+K17)
G18: =IFERROR(VLOOKUP(B18,Precios!D:E,2,0), "") | I18: =IF(G18*F18=0, "",G18*F18) | K18: =(SUM($I$8:$I$33)*C18)/-100 -> 0 | M18: =IF(I18+K18=0, "",I18+K18)
G19: =IFERROR(VLOOKUP(B19,Precios!D:E,2,0), "") | I19: =IF(G19*F19=0, "",G19*F19) | K19: =(SUM($I$8:$I$33)*C19)/-100 -> 0 | M19: =IF(I19+K19=0, "",I19+K19)
G20: =IFERROR(VLOOKUP(B20,Precios!D:E,2,0), "") | I20: =IF(G20*F20=0, "",G20*F20) | K20: =(SUM($I$8:$I$33)*C20)/-100 -> 0 | M20: =IF(I20+K20=0, "",I20+K20)
G21: =IFERROR(VLOOKUP(B21,Precios!D:E,2,0), "") | I21: =IF(G21*F21=0, "",G21*F21) | K21: =(SUM($I$8:$I$33)*C21)/-100 -> 0 | M21: =IF(I21+K21=0, "",I21+K21)
G22: =IFERROR(VLOOKUP(B22,Precios!D:E,2,0), "") | I22: =IF(G22*F22=0, "",G22*F22) | K22: =(SUM($I$8:$I$33)*C22)/-100 -> 0 | M22: =IF(I22+K22=0, "",I22+K22)
G23: =IFERROR(VLOOKUP(B23,Precios!D:E,2,0), "") | I23: =IF(G23*F23=0, "",G23*F23) | K23: =(SUM($I$8:$I$33)*C23)/-100 -> 0 | M23: =IF(I23+K23=0, "",I23+K23)
... G28: =IFERROR(VLOOKUP(B28,Precios!D:E,2,0), "") | I28: =IF(G28*F28=0, "",G28*F28) | K28: =(SUM($I$8:$I$33)*C28)/-100 -> 0 | M28: =IF(I28+K28=0, "",I28+K28)
A29: ACOMETIDAS Y TABLEROS | B29: Acometida Trifásica aérea, hasta 10kw con sistema doble aislación | G29: =IFERROR(VLOOKUP(B29,Precios!D:E,2,0), "") -> 222000 | I29: =IF(G29*F29=0, "",G29*F29) | K29: =(SUM($I$8:$I$33)*C29)/-100 -> 0 | M29: =IF(I29+K29=0, "",I29+K29)
A30: ACOMETIDAS Y TABLEROS | B30: Acometida Trifásica de 11 a 35kw | F30: 1 | G30: =IFERROR(VLOOKUP(B30,Precios!D:E,2,0), "") -> 289000 | I30: =IF(G30*F30=0, "",G30*F30) -> 289000 | K30: =(SUM($I$8:$I$33)*C30)/-100 -> 0 | M30: =IF(I30+K30=0, "",I30+K30) -> 289000
G31: =IFERROR(VLOOKUP(B31,Precios!D:E,2,0), "") | I31: =IF(G31*F31=0, "",G31*F31) | M31: =IF(I31+K31=0, "",I31+K31)
G32: =IFERROR(VLOOKUP(B32,Precios!D:E,2,0), "") | I32: =IF(G32*F32=0, "",G32*F32) | M32: =IF(I32+K32=0, "",I32+K32)
G33: =IFERROR(VLOOKUP(B33,Precios!D:E,2,0), "") | I33: =IF(G33*F33=0, "",G33*F33) | M33: =IF(I33+K33=0, "",I33+K33)
K34: subtotal (sin desc) | M34: =SUMIF(M8:M30,">0") -> 345500
K35: total descuento | M35: =SUMIF(M8:M30,"<0") -> -155475
K37: Total Neto | M37: =SUM(M34,M35) -> 190025
I39: -
A41: =IFERROR(__xludf.DUMMYFUNCTION("IMPORTRANGE(""https://docs.google.com/spreadsheets/d/1aPynYCYBaEafPC4rqTulMOzPg_guy_NLzZHOzvFJwyw/edit?usp=drivesdk"", ""Respuestas de formulario 1!C5"")"),3.513559347E9) -> 3513559347

Sheet Copia_de_Carga
A2: Fecha | B2: 46067
A3: Nombre | B3: Pepito monje
A4: Dirección | B4: =VLOOKUP(B3,Clientes!B2:D200,3,0) -> Guntanamera 1020
A6: Tema | B6: Concepto | C6: descuento | F6: Cantidad | G6: Valor | I6: sub | K6: descuentos en % | M6: concatenado
C7: porcentaje | D7: % | E7: detalle
B8: =Hoja8!A2 -> 46072 | F8: =Hoja8!B2 -> Villagrono Alfredus | G8: =IFERROR(VLOOKUP(B8,Precios!D:E,2,0), "") | I8: =IF(G8*F8=0, "",G8*F8) -> #VALUE! | K8: =(SUM($I$8:$I$33)*C8)/-100 -> #VALUE! | M8: =IF(I8+K8=0, "",I8+K8) -> #VALUE!
B9: =Hoja8!A3 -> Instalación a altura h<4mts con perfil C P/ BPC 100 a 300 | F9: =Hoja8!B3 -> 1 | G9: =IFERROR(VLOOKUP(B9,Precios!D:E,2,0), "") -> 51700 | I9: =IF(G9*F9=0, "",G9*F9) -> 51700 | K9: =(SUM($I$8:$I$33)*C9)/-100 -> #VALUE! | M9: =IF(I9+K9=0, "",I9+K9) -> #VALUE!
B10: =Hoja8!A4 -> Instalación a altura h<4mts con perfil C P/ BPC 100 a 300 | F10: =Hoja8!B4 -> 1 | G10: =IFERROR(VLOOKUP(B10,Precios!D:E,2,0), "") -> 51700 | I10: =IF(G10*F10=0, "",G10*F10) -> 51700 | K10: =(SUM($I$8:$I$33)*C10)/-100 -> #VALUE! | M10: =IF(I10+K10=0, "",I10+K10) -> #VALUE!
B11: =Hoja8!A5 -> Instalación a altura h<4mts con perfil C P/ BPC 100 a 300 | D11: % | F11: =Hoja8!B5 -> 1 | G11: =IFERROR(VLOOKUP(B11,Precios!D:E,2,0), "") -> 51700 | I11: =IF(G11*F11=0, "",G11*F11) -> 51700 | K11: =(SUM($I$8:$I$33)*C11)/-100 -> #VALUE! | M11: =IF(I11+K11=0, "",I11+K11) -> #VALUE!
B12: =Hoja8!A6 -> Instalación a altura h<4mts con perfil C P/ BPC 100 a 300 | F12: =Hoja8!B6 -> 1 | G12: =IFERROR(VLOOKUP(B12,Precios!D:E,2,0), "") -> 51700 | I12: =IF(G12*F12=0, "",G12*F12) -> 51700 | K12: =(SUM($I$8:$I$33)*C12)/-100 -> #VALUE! | M12: =IF(I12+K12=0, "",I12+K12) -> #VALUE!
B13: =Hoja8!A7 -> Instalación a altura h<4mts con perfil C P/ BPC 100 a 300 | F13: =Hoja8!B7 -> 1 | G13: =IFERROR(VLOOKUP(B13,Precios!D:E,2,0), "") -> 51700 | I13: =IF(G13*F13=0, "",G13*F13) -> 51700 | K13: =(SUM($I$8:$I$33)*C13)/-100 -> #VALUE! | M13: =IF(I13+K13=0, "",I13+K13) -> #VALUE!
B14: =Hoja8!A8 -> Instalación a altura h<4mts con perfil C P/ BPC 100 a 300 | F14: =Hoja8!B8 -> 1 | G14: =IFERROR(VLOOKUP(B14,Precios!D:E,2,0), "") -> 51700 | I14: =IF(G14*F14=0, "",G14*F14) -> 51700 | K14: =(SUM($I$8:$I$33)*C14)/-100 -> #VALUE! | M14: =IF(I14+K14=0, "",I14+K14) -> #VALUE!
B15: =Hoja8!A9 -> Certificacion de vivienda o local comercial (hasta 20bocas) no incluye adecuacion de la instalacion | F15: =Hoja8!B9 -> -2 | G15: =IFERROR(VLOOKUP(B15,Precios!D:E,2,0), "") | I15: =IF(G15*F15=0, "",G15*F15) | K15: =(SUM($I$8:$I$33)*C15)/-100 -> #VALUE! | M15: =IF(I15+K15=0, "",I15+K15) -> #VALUE!
B16: =Hoja8!A10 -> Certificacion de vivienda o local comercial (hasta 20bocas) no incluye adecuacion de la instalacion | F16: =Hoja8!B10 -> -2 | G16: =IFERROR(VLOOKUP(B16,Precios!D:E,2,0), "") | I16: =IF(G16*F16=0, "",G16*F16) | K16: =(SUM($I$8:$I$33)*C16)/-100 -> #VALUE! | M16: =IF(I16+K16=0, "",I16+K16) -> #VALUE!
B17: =Hoja8!A11 -> Certificacion de vivienda o local comercial (hasta 20bocas) no incluye adecuacion de la instalacion | F17: =Hoja8!B11 -> -2 | G17: =IFERROR(VLOOKUP(B17,Precios!D:E,2,0), "") | I17: =IF(G17*F17=0, "",G17*F17) | K17: =(SUM($I$8:$I$33)*C17)/-100 -> #VALUE! | M17: =IF(I17+K17=0, "",I17+K17) -> #VALUE!
B18: =Hoja8!A12 -> Certificacion de vivienda o local comercial (hasta 20bocas) no incluye adecuacion de la instalacion | F18: =Hoja8!B12 -> -2 | G18: =IFERROR(VLOOKUP(B18,Precios!D:E,2,0), "") | I18: =IF(G18*F18=0, "",G18*F18) | K18: =(SUM($I$8:$I$33)*C18)/-100 -> #VALUE! | M18: =IF(I18+K18=0, "",I18+K18) -> #VALUE!
B19: =Hoja8!A13 -> Certificacion de vivienda o local comercial (hasta 20bocas) no incluye adecuacion de la instalacion | F19: =Hoja8!B13 -> -2 | G19: =IFERROR(VLOOKUP(B19,Precios!D:E,2,0), "") | I19: =IF(G19*F19=0, "",G19*F19) | K19: =(SUM($I$8:$I$33)*C19)/-100 -> #VALUE! | M19: =IF(I19+K19=0, "",I19+K19) -> #VALUE!
B20: =Hoja8!A14 -> Certificacion de vivienda o local comercial (hasta 20bocas) no incluye adecuacion de la instalacion | F20: =Hoja8!B14 -> -2 | G20: =IFERROR(VLOOKUP(B20,Precios!D:E,2,0), "") | I20: =IF(G20*F20=0, "",G20*F20) | K20: =(SUM($I$8:$I$33)*C20)/-100 -> #VALUE! | M20: =IF(I20+K20=0, "",I20+K20) -> #VALUE!
B21: =Hoja8!A15 -> Certificacion de vivienda o local comercial (hasta 20bocas) no incluye adecuacion de la instalacion | F21: =Hoja8!B15 -> -2 | G21: =IFERROR(VLOOKUP(B21,Precios!D:E,2,0), "") | I21: =IF(G21*F21=0, "",G21*F21) | K21: =(SUM($I$8:$I$33)*C21)/-100 -> #VALUE! | M21: =IF(I21+K21=0, "",I21+K21) -> #VALUE!
B22: =Hoja8!A16 -> Certificacion de vivienda o local comercial (hasta 20bocas) no incluye adecuacion de la instalacion | F22: =Hoja8!B16 -> -2 | G22: =IFERROR(VLOOKUP(B22,Precios!D:E,2,0), "") | I22: =IF(G22*F22=0, "",G22*F22) | K22: =(SUM($I$8:$I$33)*C22)/-100 -> #VALUE! | M22: =IF(I22+K22=0, "",I22+K22) -> #VALUE!
B23: =Hoja8!A17 -> Certificacion de vivienda o local comercial (hasta 20bocas) no incluye adecuacion de la instalacion | F23: =Hoja8!B17 -> -2 | G23: =IFERROR(VLOOKUP(B23,Precios!D:E,2,0), "") | I23: =IF(G23*F23=0, "",G23*F23) | K23: =(SUM($I$8:$I$33)*C23)/-100 -> #VALUE! | M23: =IF(I23+K23=0, "",I23+K23) -> #VALUE!
... B26: =Hoja8!A20 -> Certificacion de vivienda o local comercial (hasta 20bocas) no incluye adecuacion de la instalacion | F26: =Hoja8!B20 -> -2 | G26: =IFERROR(VLOOKUP(B26,Precios!D:E,2,0), "") | I26: =IF(G26*F26=0, "",G26*F26) | K26: =(SUM($I$8:$I$33)*C26)/-100 -> #VALUE! | M26: =IF(I26+K26=0, "",I26+K26) -> #VALUE!
B27: =Hoja8!A21 -> Certificacion de vivienda o local comercial (hasta 20bocas) no incluye adecuacion de la instalacion | F27: =Hoja8!B21 -> -2 | G27: =Hoja8!C21 | I27: =IF(G27*F27=0, "",G27*F27) | K27: =(SUM($I$8:$I$33)*C27)/-100 -> #VALUE! | M27: =IF(I27+K27=0, "",I27+K27) -> #VALUE!
B28: =Hoja8!A22 -> Certificacion de vivienda o local comercial (hasta 20bocas) no incluye adecuacion de la instalacion | F28: =Hoja8!B22 -> -2 | G28: =Hoja8!C22 | I28: =IF(G28*F28=0, "",G28*F28) | K28: =(SUM($I$8:$I$33)*C28)/-100 -> #VALUE! | M28: =IF(I28+K28=0, "",I28+K28) -> #VALUE!
A29: ACOMETIDAS Y TABLEROS | B29: =Hoja8!A23 -> Certificacion de vivienda o local comercial (hasta 20bocas) no incluye adecuacion de la instalacion | F29: =Hoja8!B23 -> -2 | G29: =Hoja8!C23 | I29: =IF(G29*F29=0, "",G29*F29) | K29: =(SUM($I$8:$I$33)*C29)/-100 -> #VALUE! | M29: =IF(I29+K29=0, "",I29+K29) -> #VALUE!
A30: ACOMETIDAS Y TABLEROS | B30: =Hoja8!A24 -> Certificacion de vivienda o local comercial (hasta 20bocas) no incluye adecuacion de la instalacion | F30: =Hoja8!B24 -> -2 | G30: =Hoja8!C24 | I30: =IF(G30*F30=0, "",G30*F30) | K30: =(SUM($I$8:$I$33)*C30)/-100 -> #VALUE! | M30: =IF(I30+K30=0, "",I30+K30) -> #VALUE!
G31: =IFERROR(VLOOKUP(B31,Precios!D:E,2,0), "") | I31: =IF(G31*F31=0, "",G31*F31) | M31: =IF(I31+K31=0, "",I31+K31)
G32: =IFERROR(VLOOKUP(B32,Precios!D:E,2,0), "") | I32: =IF(G32*F32=0, "",G32*F32) | M32: =IF(I32+K32=0, "",I32+K32)
G33: =IFERROR(VLOOKUP(B33,Precios!D:E,2,0), "") | I33: =IF(G33*F33=0, "",G33*F33) | M33: =IF(I33+K33=0, "",I33+K33)
K34: subtotal (sin desc) | M34: =SUMIF(M8:M30,">0") -> 0
K35: total descuento | M35: =SUMIF(M8:M30,"<0") -> 0
K37: Total Neto | M37: =SUM(M34,M35) -> 0
I39: -
A41: =IFERROR(__xludf.DUMMYFUNCTION("IMPORTRANGE(""https://docs.google.com/spreadsheets/d/1aPynYCYBaEafPC4rqTulMOzPg_guy_NLzZHOzvFJwyw/edit?usp=drivesdk"", ""Respuestas de formulario 1!C5"")"),3.513559347E9) -> 3513559347

Sheet F1
A1: =IFERROR(__xludf.DUMMYFUNCTION("FILTER(Precios!$D:$D,Carga!A8=Precios!$C:$C)"),"#N/A") -> #N/A | B1: =IFERROR(__xludf.DUMMYFUNCTION("FILTER(Precios!$D:$D,Carga!A9=Precios!$C:$C)"),"#N/A") -> #N/A | C1: =IFERROR(__xludf.DUMMYFUNCTION("FILTER(Precios!$D:$D,Carga!A10=Precios!$C:$C)"),"#N/A") -> #N/A | D1: =IFERROR(__xludf.DUMMYFUNCTION("FILTER(Precios!$D:$D,Carga!A11=Precios!$C:$C)"),"#N/A") -> #N/A | E1: =IFERROR(__xludf.DUMMYFUNCTION("FILTER(Precios!$D:$D,Carga!A12=Precios!$C:$C)"),"") | F1: =IFERROR(__xludf.DUMMYFUNCTION("FILTER(Precios!$D:$D,Carga!A13=Precios!$C:$C)"),"") | G1: =IFERROR(__xludf.DUMMYFUNCTION("FILTER(Precios!$D:$D,Carga!A14=Precios!$C:$C)"),"") | H1: =IFERROR(__xludf.DUMMYFUNCTION("FILTER(Precios!$D:$D,Carga!A15=Precios!$C:$C)"),"") | I1: =IFERROR(__xludf.DUMMYFUNCTION("FILTER(Precios!$D:$D,Carga!A16=Precios!$C:$C)"),"") | J1: =IFERROR(__xludf.DUMMYFUNCTION("FILTER(Precios!$D:$D,Carga!A17=Precios!$C:$C)"),"") | K1: =IFERROR(__xludf.DUMMYFUNCTION("FILTER(Precios!$D:$D,Carga!A18=Precios!$C:$C)"),"") | L1: =IFERROR(__xludf.DUMMYFUNCTION("FILTER(Precios!$D:$D,Carga!A19=Precios!$C:$C)"),"") | M1: =IFERROR(__xludf.DUMMYFUNCTION("FILTER(Precios!$D:$D,Carga!A20=Precios!$C:$C)"),"") | N1: =IFERROR(__xludf.DUMMYFUNCTION("FILTER(Precios!$D:$D,Carga!A21=Precios!$C:$C)"),"") | O1: =IFERROR(__xludf.DUMMYFUNCTION("FILTER(Precios!$D:$D,Carga!A22=Precios!$C:$C)"),"") | P1: =IFERROR(__xludf.DUMMYFUNCTION("FILTER(Precios!$D:$D,Carga!A23=Precios!$C:$C)"),"") | Q1: =IFERROR(__xludf.DUMMYFUNCTION("FILTER(Precios!$D:$D,Carga!A24=Precios!$C:$C)"),"") | R1: =IFERROR(__xludf.DUMMYFUNCTION("FILTER(Precios!$D:$D,Carga!A25=Precios!$C:$C)"),"") | S1: =IFERROR(__xludf.DUMMYFUNCTION("FILTER(Precios!$D:$D,Carga!A26=Precios!$C:$C)"),"") | T1: =IFERROR(__xludf.DUMMYFUNCTION("FILTER(Precios!$D:$D,Carga!A27=Precios!$C:$C)"),"") | U1: =IFERROR(__xludf.DUMMYFUNCTION("FILTER(Precios!$D:$D,Carga!A28=Precios!$C:$C)"),"") | V1: =IFERROR(__xludf.DUMMYFUNCTION("FILTER(Precios!$D:$D,Carga!A29=Precios!$C:$C)"),"Acometida Monofásica aérea, con sistema doble aislación") -> Acometida Monofásica aérea, con sistema doble aislación | W1: =IFERROR(__xludf.DUMMYFUNCTION("FILTER(Precios!$D:$D,Carga!A30=Precios!$C:$C)"),"Acometida Monofásica aérea, con sistema doble aislación") -> Acometida Monofásica aérea, con sistema doble aislación
V2: =IFERROR(__xludf.DUMMYFUNCTION("""COMPUTED_VALUE"""),"Acometida Trifásica aérea, hasta 10kw con sistema doble aislación") -> Acometida Trifásica aérea, hasta 10kw con sistema doble aislación | W2: =IFERROR(__xludf.DUMMYFUNCTION("""COMPUTED_VALUE"""),"Acometida Trifásica aérea, hasta 10kw con sistema doble aislación") -> Acometida Trifásica aérea, hasta 10kw con sistema doble aislación
V3: =IFERROR(__xludf.DUMMYFUNCTION("""COMPUTED_VALUE"""),"Acometida subterránea, hasta 10kw con sistema doble aislación") -> Acometida subterránea, hasta 10kw con sistema doble aislación | W3: =IFERROR(__xludf.DUMMYFUNCTION("""COMPUTED_VALUE"""),"Acometida subterránea, hasta 10kw con sistema doble aislación") -> Acometida subterránea, hasta 10kw con sistema doble aislación
V4: =IFERROR(__xludf.DUMMYFUNCTION("""COMPUTED_VALUE"""),"Acometida Trifásica de 11 a 35kw") -> Acometida Trifásica de 11 a 35kw | W4: =IFERROR(__xludf.DUMMYFUNCTION("""COMPUTED_VALUE"""),"Acometida Trifásica de 11 a 35kw") -> Acometida Trifásica de 11 a 35kw
V5: =IFERROR(__xludf.DUMMYFUNCTION("""COMPUTED_VALUE"""),"Acometida Trifásica de 36 a 50kw") -> Acometida Trifásica de 36 a 50kw | W5: =IFERROR(__xludf.DUMMYFUNCTION("""COMPUTED_VALUE"""),"Acometida Trifásica de 36 a 50kw") -> Acometida Trifásica de 36 a 50kw
V6: =IFERROR(__xludf.DUMMYFUNCTION("""COMPUTED_VALUE"""),"Acometida Trifásica mas de 50kw") -> Acometida Trifásica mas de 50kw | W6: =IFERROR(__xludf.DUMMYFUNCTION("""COMPUTED_VALUE"""),"Acometida Trifásica mas de 50kw") -> Acometida Trifásica mas de 50kw
V7: =IFERROR(__xludf.DUMMYFUNCTION("""COMPUTED_VALUE"""),"Fijación tablero de superficie (hasta 54 bocas)") -> Fijación tablero de superficie (hasta 54 bocas) | W7: =IFERROR(__xludf.DUMMYFUNCTION("""COMPUTED_VALUE"""),"Fijación tablero de superficie (hasta 54 bocas)") -> Fijación tablero de superficie (hasta 54 bocas)
V8: =IFERROR(__xludf.DUMMYFUNCTION("""COMPUTED_VALUE"""),"Fijación tablero de superficie") -> Fijación tablero de superficie | W8: =IFERROR(__xludf.DUMMYFUNCTION("""COMPUTED_VALUE"""),"Fijación tablero de superficie") -> Fijación tablero de superficie
V9: =IFERROR(__xludf.DUMMYFUNCTION("""COMPUTED_VALUE"""),"Empotrado de gabinete en mampostería (de 1 a 24 bocas)") -> Empotrado de gabinete en mampostería (de 1 a 24 bocas) | W9: =IFERROR(__xludf.DUMMYFUNCTION("""COMPUTED_VALUE"""),"Empotrado de gabinete en mampostería (de 1 a 24 bocas)") -> Empotrado de gabinete en mampostería (de 1 a 24 bocas)
V10: =IFERROR(__xludf.DUMMYFUNCTION("""COMPUTED_VALUE"""),"Empotrado / Fijación de gabinete en mampostería") -> Empotrado / Fijación de gabinete en mampostería | W10: =IFERROR(__xludf.DUMMYFUNCTION("""COMPUTED_VALUE"""),"Empotrado / Fijación de gabinete en mampostería") -> Empotrado / Fijación de gabinete en mampostería
V11: =IFERROR(__xludf.DUMMYFUNCTION("""COMPUTED_VALUE"""),"Empotrado de gabinete en mampostería (de 25 a 54 bocas)") -> Empotrado de gabinete en mampostería (de 25 a 54 bocas) | W11: =IFERROR(__xludf.DUMMYFUNCTION("""COMPUTED_VALUE"""),"Empotrado de gabinete en mampostería (de 25 a 54 bocas)") -> Empotrado de gabinete en mampostería (de 25 a 54 bocas)
V12: =IFERROR(__xludf.DUMMYFUNCTION("""COMPUTED_VALUE"""),"Armado de tablero de obra") -> Armado de tablero de obra | W12: =IFERROR(__xludf.DUMMYFUNCTION("""COMPUTED_VALUE"""),"Armado de tablero de obra") -> Armado de tablero de obra
V13: =IFERROR(__xludf.DUMMYFUNCTION("""COMPUTED_VALUE"""),"Zanjeo x metro ( 25 x 80cm) mas tendido de cable subterraneo hasta 4x10mm y relleno con protecciones mecánicas para longitudes de cable menor a 10 metros") -> Zanjeo x metro ( 25 x 80cm) mas tendido de cable subterraneo hasta 4x10mm y relleno con protecciones mecánicas para longitudes de cable menor a 10 metros | W13: =IFERROR(__xludf.DUMMYFUNCTION("""COMPUTED_VALUE"""),"Zanjeo x metro ( 25 x 80cm) mas tendido de cable subterraneo hasta 4x10mm y relleno con protecciones mecánicas para longitudes de cable menor a 10 metros") -> Zanjeo x metro ( 25 x 80cm) mas tendido de cable subterraneo hasta 4x10mm y relleno con protecciones mecánicas para longitudes de cable menor a 10 metros
V14: =IFERROR(__xludf.DUMMYFUNCTION("""COMPUTED_VALUE"""),"Zanjeo x metro ( 25 x 80cm) mas tendido de cable subterraneo hasta 4x10mm y relleno con protecciones mecánicas para longitudes de cable mayor a 10 metros") -> Zanjeo x metro ( 25 x 80cm) mas tendido de cable subterraneo hasta 4x10mm y relleno con protecciones mecánicas para longitudes de cable mayor a 10 metros | W14: =IFERROR(__xludf.DUMMYFUNCTION("""COMPUTED_VALUE"""),"Zanjeo x metro ( 25 x 80cm) mas tendido de cable subterraneo hasta 4x10mm y relleno con protecciones mecánicas para longitudes de cable mayor a 10 metros") -> Zanjeo x metro ( 25 x 80cm) mas tendido de cable subterraneo hasta 4x10mm y relleno con protecciones mecánicas para longitudes de cable mayor a 10 metros
V15: =IFERROR(__xludf.DUMMYFUNCTION("""COMPUTED_VALUE"""),"Puesta a tierra: jabalina+caja de inspección") -> Puesta a tierra: jabalina+caja de inspección | W15: =IFERROR(__xludf.DUMMYFUNCTION("""COMPUTED_VALUE"""),"Puesta a tierra: jabalina+caja de inspección") -> Puesta a tierra: jabalina+caja de inspección
E427: =IFERROR(__xludf.DUMMYFUNCTION("""COMPUTED_VALUE"""),"DOCUMENTACIÓN, CERTIFICACIÓN Y SERVICIO DE MEDICIÓN") -> DOCUMENTACIÓN, CERTIFICACIÓN Y SERVICIO DE MEDICIÓN | F427: =IFERROR(__xludf.DUMMYFUNCTION("""COMPUTED_VALUE"""),"DOCUMENTACIÓN, CERTIFICACIÓN Y SERVICIO DE MEDICIÓN") -> DOCUMENTACIÓN, CERTIFICACIÓN Y SERVICIO DE MEDICIÓN | G427: =IFERROR(__xludf.DUMMYFUNCTION("""COMPUTED_VALUE"""),"DOCUMENTACIÓN, CERTIFICACIÓN Y SERVICIO DE MEDICIÓN") -> DOCUMENTACIÓN, CERTIFICACIÓN Y SERVICIO DE MEDICIÓN | H427: =IFERROR(__xludf.DUMMYFUNCTION("""COMPUTED_VALUE"""),"DOCUMENTACIÓN, CERTIFICACIÓN Y SERVICIO DE MEDICIÓN") -> DOCUMENTACIÓN, CERTIFICACIÓN Y SERVICIO DE MEDICIÓN | I427: =IFERROR(__xludf.DUMMYFUNCTION("""COMPUTED_VALUE"""),"DOCUMENTACIÓN, CERTIFICACIÓN Y SERVICIO DE MEDICIÓN") -> DOCUMENTACIÓN, CERTIFICACIÓN Y SERVICIO DE MEDICIÓN | J427: =IFERROR(__xludf.DUMMYFUNCTION("""COMPUTED_VALUE"""),"DOCUMENTACIÓN, CERTIFICACIÓN Y SERVICIO DE MEDICIÓN") -> DOCUMENTACIÓN, CERTIFICACIÓN Y SERVICIO DE MEDICIÓN | K427: =IFERROR(__xludf.DUMMYFUNCTION("""COMPUTED_VALUE"""),"DOCUMENTACIÓN, CERTIFICACIÓN Y SERVICIO DE MEDICIÓN") -> DOCUMENTACIÓN, CERTIFICACIÓN Y SERVICIO DE MEDICIÓN | L427: =IFERROR(__xludf.DUMMYFUNCTION("""COMPUTED_VALUE"""),"DOCUMENTACIÓN, CERTIFICACIÓN Y SERVICIO DE MEDICIÓN") -> DOCUMENTACIÓN, CERTIFICACIÓN Y SERVICIO DE MEDICIÓN | ... U427: =IFERROR(__xludf.DUMMYFUNCTION("""COMPUTED_VALUE"""),"DOCUMENTACIÓN, CERTIFICACIÓN Y SERVICIO DE MEDICIÓN") -> DOCUMENTACIÓN, CERTIFICACIÓN Y SERVICIO DE MEDICIÓN
E428: =IFERROR(__xludf.DUMMYFUNCTION("""COMPUTED_VALUE"""),"ACOMETIDAS Y TABLEROS") -> ACOMETIDAS Y TABLEROS | F428: =IFERROR(__xludf.DUMMYFUNCTION("""COMPUTED_VALUE"""),"ACOMETIDAS Y TABLEROS") -> ACOMETIDAS Y TABLEROS | G428: =IFERROR(__xludf.DUMMYFUNCTION("""COMPUTED_VALUE"""),"ACOMETIDAS Y TABLEROS") -> ACOMETIDAS Y TABLEROS | H428: =IFERROR(__xludf.DUMMYFUNCTION("""COMPUTED_VALUE"""),"ACOMETIDAS Y TABLEROS") -> ACOMETIDAS Y TABLEROS | I428: =IFERROR(__xludf.DUMMYFUNCTION("""COMPUTED_VALUE"""),"ACOMETIDAS Y TABLEROS") -> ACOMETIDAS Y TABLEROS | J428: =IFERROR(__xludf.DUMMYFUNCTION("""COMPUTED_VALUE"""),"ACOMETIDAS Y TABLEROS") -> ACOMETIDAS Y TABLEROS | K428: =IFERROR(__xludf.DUMMYFUNCTION("""COMPUTED_VALUE"""),"ACOMETIDAS Y TABLEROS") -> ACOMETIDAS Y TABLEROS | L428: =IFERROR(__xludf.DUMMYFUNCTION("""COMPUTED_VALUE"""),"ACOMETIDAS Y TABLEROS") -> ACOMETIDAS Y TABLEROS | ... U428: =IFERROR(__xludf.DUMMYFUNCTION("""COMPUTED_VALUE"""),"ACOMETIDAS Y TABLEROS") -> ACOMETIDAS Y TABLEROS
E429: =IFERROR(__xludf.DUMMYFUNCTION("""COMPUTED_VALUE"""),"CANALIZACIÓN EMBUTIDA") -> CANALIZACIÓN EMBUTIDA | F429: =IFERROR(__xludf.DUMMYFUNCTION("""COMPUTED_VALUE"""),"CANALIZACIÓN EMBUTIDA") -> CANALIZACIÓN EMBUTIDA | G429: =IFERROR(__xludf.DUMMYFUNCTION("""COMPUTED_VALUE"""),"CANALIZACIÓN EMBUTIDA") -> CANALIZACIÓN EMBUTIDA | H429: =IFERROR(__xludf.DUMMYFUNCTION("""COMPUTED_VALUE"""),"CANALIZACIÓN EMBUTIDA") -> CANALIZACIÓN EMBUTIDA | I429: =IFERROR(__xludf.DUMMYFUNCTION("""COMPUTED_VALUE"""),"CANALIZACIÓN EMBUTIDA") -> CANALIZACIÓN EMBUTIDA | J429: =IFERROR(__xludf.DUMMYFUNCTION("""COMPUTED_VALUE"""),"CANALIZACIÓN EMBUTIDA") -> CANALIZACIÓN EMBUTIDA | K429: =IFERROR(__xludf.DUMMYFUNCTION("""COMPUTED_VALUE"""),"CANALIZACIÓN EMBUTIDA") -> CANALIZACIÓN EMBUTIDA | L429: =IFERROR(__xludf.DUMMYFUNCTION("""COMPUTED_VALUE"""),"CANALIZACIÓN EMBUTIDA") -> CANALIZACIÓN EMBUTIDA | ... U429: =IFERROR(__xludf.DUMMYFUNCTION("""COMPUTED_VALUE"""),"CANALIZACIÓN EMBUTIDA") -> CANALIZACIÓN EMBUTIDA
E430: =IFERROR(__xludf.DUMMYFUNCTION("""COMPUTED_VALUE"""),"CANALIZACIÓN EMBUTIDA EN DURLOCK") -> CANALIZACIÓN EMBUTIDA EN DURLOCK | F430: =IFERROR(__xludf.DUMMYFUNCTION("""COMPUTED_VALUE"""),"CANALIZACIÓN EMBUTIDA EN DURLOCK") -> CANALIZACIÓN EMBUTIDA EN DURLOCK | G430: =IFERROR(__xludf.DUMMYFUNCTION("""COMPUTED_VALUE"""),"CANALIZACIÓN EMBUTIDA EN DURLOCK") -> CANALIZACIÓN EMBUTIDA EN DURLOCK | H430: =IFERROR(__xludf.DUMMYFUNCTION("""COMPUTED_VALUE"""),"CANALIZACIÓN EMBUTIDA EN DURLOCK") -> CANALIZACIÓN EMBUTIDA EN DURLOCK | I430: =IFERROR(__xludf.DUMMYFUNCTION("""COMPUTED_VALUE"""),"CANALIZACIÓN EMBUTIDA EN DURLOCK") -> CANALIZACIÓN EMBUTIDA EN DURLOCK | J430: =IFERROR(__xludf.DUMMYFUNCTION("""COMPUTED_VALUE"""),"CANALIZACIÓN EMBUTIDA EN DURLOCK") -> CANALIZACIÓN EMBUTIDA EN DURLOCK | K430: =IFERROR(__xludf.DUMMYFUNCTION("""COMPUTED_VALUE"""),"CANALIZACIÓN EMBUTIDA EN DURLOCK") -> CANALIZACIÓN EMBUTIDA EN DURLOCK | L430: =IFERROR(__xludf.DUMMYFUNCTION("""COMPUTED_VALUE"""),"CANALIZACIÓN EMBUTIDA EN DURLOCK") -> CANALIZACIÓN EMBUTIDA EN DURLOCK | ... U430: =IFERROR(__xludf.DUMMYFUNCTION("""COMPUTED_VALUE"""),"CANALIZACIÓN EMBUTIDA EN DURLOCK") -> CANALIZACIÓN EMBUTIDA EN DURLOCK
E431: =IFERROR(__xludf.DUMMYFUNCTION("""COMPUTED_VALUE"""),"CANALIZACIÓN EXTERIOR ") -> CANALIZACIÓN EXTERIOR | F431: =IFERROR(__xludf.DUMMYFUNCTION("""COMPUTED_VALUE"""),"CANALIZACIÓN EXTERIOR ") -> CANALIZACIÓN EXTERIOR | G431: =IFERROR(__xludf.DUMMYFUNCTION("""COMPUTED_VALUE"""),"CANALIZACIÓN EXTERIOR ") -> CANALIZACIÓN EXTERIOR | H431: =IFERROR(__xludf.DUMMYFUNCTION("""COMPUTED_VALUE"""),"CANALIZACIÓN EXTERIOR ") -> CANALIZACIÓN EXTERIOR | I431: =IFERROR(__xludf.DUMMYFUNCTION("""COMPUTED_VALUE"""),"CANALIZACIÓN EXTERIOR ") -> CANALIZACIÓN EXTERIOR | J431: =IFERROR(__xludf.DUMMYFUNCTION("""COMPUTED_VALUE"""),"CANALIZACIÓN EXTERIOR ") -> CANALIZACIÓN EXTERIOR | K431: =IFERROR(__xludf.DUMMYFUNCTION("""COMPUTED_VALUE"""),"CANALIZACIÓN EXTERIOR ") -> CANALIZACIÓN EXTERIOR | L431: =IFERROR(__xludf.DUMMYFUNCTION("""COMPUTED_VALUE"""),"CANALIZACIÓN EXTERIOR ") -> CANALIZACIÓN EXTERIOR | ... U431: =IFERROR(__xludf.DUMMYFUNCTION("""COMPUTED_VALUE"""),"CANALIZACIÓN EXTERIOR ") -> CANALIZACIÓN EXTERIOR
E432: =IFERROR(__xludf.DUMMYFUNCTION("""COMPUTED_VALUE"""),"CANALIZACIÓN DE CABLE CANAL") -> CANALIZACIÓN DE CABLE CANAL | F432: =IFERROR(__xludf.DUMMYFUNCTION("""COMPUTED_VALUE"""),"CANALIZACIÓN DE CABLE CANAL") -> CANALIZACIÓN DE CABLE CANAL | G432: =IFERROR(__xludf.DUMMYFUNCTION("""COMPUTED_VALUE"""),"CANALIZACIÓN DE CABLE CANAL") -> CANALIZACIÓN DE CABLE CANAL | H432: =IFERROR(__xludf.DUMMYFUNCTION("""COMPUTED_VALUE"""),"CANALIZACIÓN DE CABLE CANAL") -> CANALIZACIÓN DE CABLE CANAL | I432: =IFERROR(__xludf.DUMMYFUNCTION("""COMPUTED_VALUE"""),"CANALIZACIÓN DE CABLE CANAL") -> CANALIZACIÓN DE CABLE CANAL | J432: =IFERROR(__xludf.DUMMYFUNCTION("""COMPUTED_VALUE"""),"CANALIZACIÓN DE CABLE CANAL") -> CANALIZACIÓN DE CABLE CANAL | K432: =IFERROR(__xludf.DUMMYFUNCTION("""COMPUTED_VALUE"""),"CANALIZACIÓN DE CABLE CANAL") -> CANALIZACIÓN DE CABLE CANAL | L432: =IFERROR(__xludf.DUMMYFUNCTION("""COMPUTED_VALUE"""),"CANALIZACIÓN DE CABLE CANAL") -> CANALIZACIÓN DE CABLE CANAL | ... U432: =IFERROR(__xludf.DUMMYFUNCTION("""COMPUTED_VALUE"""),"CANALIZACIÓN DE CABLE CANAL") -> CANALIZACIÓN DE CABLE CANAL
E433: =IFERROR(__xludf.DUMMYFUNCTION("""COMPUTED_VALUE"""),"CANALIZACIÓN Y CABLEADO CON PISO DUCTOS / POLIDUCTOS ") -> CANALIZACIÓN Y CABLEADO CON PISO DUCTOS / POLIDUCTOS | F433: =IFERROR(__xludf.DUMMYFUNCTION("""COMPUTED_VALUE"""),"CANALIZACIÓN Y CABLEADO CON PISO DUCTOS / POLIDUCTOS ") -> CANALIZACIÓN Y CABLEADO CON PISO DUCTOS / POLIDUCTOS | G433: =IFERROR(__xludf.DUMMYFUNCTION("""COMPUTED_VALUE"""),"CANALIZACIÓN Y CABLEADO CON PISO DUCTOS / POLIDUCTOS ") -> CANALIZACIÓN Y CABLEADO CON PISO DUCTOS / POLIDUCTOS | H433: =IFERROR(__xludf.DUMMYFUNCTION("""COMPUTED_VALUE"""),"CANALIZACIÓN Y CABLEADO CON PISO DUCTOS / POLIDUCTOS ") -> CANALIZACIÓN Y CABLEADO CON PISO DUCTOS / POLIDUCTOS | I433: =IFERROR(__xludf.DUMMYFUNCTION("""COMPUTED_VALUE"""),"CANALIZACIÓN Y CABLEADO CON PISO DUCTOS / POLIDUCTOS ") -> CANALIZACIÓN Y CABLEADO CON PISO DUCTOS / POLIDUCTOS | J433: =IFERROR(__xludf.DUMMYFUNCTION("""COMPUTED_VALUE"""),"CANALIZACIÓN Y CABLEADO CON PISO DUCTOS / POLIDUCTOS ") -> CANALIZACIÓN Y CABLEADO CON PISO DUCTOS / POLIDUCTOS | K433: =IFERROR(__xludf.DUMMYFUNCTION("""COMPUTED_VALUE"""),"CANALIZACIÓN Y CABLEADO CON PISO DUCTOS / POLIDUCTOS ") -> CANALIZACIÓN Y CABLEADO CON PISO DUCTOS / POLIDUCTOS | L433: =IFERROR(__xludf.DUMMYFUNCTION("""COMPUTED_VALUE"""),"CANALIZACIÓN Y CABLEADO CON PISO DUCTOS / POLIDUCTOS ") -> CANALIZACIÓN Y CABLEADO CON PISO DUCTOS / POLIDUCTOS | ... U433: =IFERROR(__xludf.DUMMYFUNCTION("""COMPUTED_VALUE"""),"CANALIZACIÓN Y CABLEADO CON PISO DUCTOS / POLIDUCTOS ") -> CANALIZACIÓN Y CABLEADO CON PISO DUCTOS / POLIDUCTOS
E434: =IFERROR(__xludf.DUMMYFUNCTION("""COMPUTED_VALUE"""),"CANALIZACIÓN CON BANDEJAS PORTA CABLES Y PERFIL C") -> CANALIZACIÓN CON BANDEJAS PORTA CABLES Y PERFIL C | F434: =IFERROR(__xludf.DUMMYFUNCTION("""COMPUTED_VALUE"""),"CANALIZACIÓN CON BANDEJAS PORTA CABLES Y PERFIL C") -> CANALIZACIÓN CON BANDEJAS PORTA CABLES Y PERFIL C | G434: =IFERROR(__xludf.DUMMYFUNCTION("""COMPUTED_VALUE"""),"CANALIZACIÓN CON BANDEJAS PORTA CABLES Y PERFIL C") -> CANALIZACIÓN CON BANDEJAS PORTA CABLES Y PERFIL C | H434: =IFERROR(__xludf.DUMMYFUNCTION("""COMPUTED_VALUE"""),"CANALIZACIÓN CON BANDEJAS PORTA CABLES Y PERFIL C") -> CANALIZACIÓN CON BANDEJAS PORTA CABLES Y PERFIL C | I434: =IFERROR(__xludf.DUMMYFUNCTION("""COMPUTED_VALUE"""),"CANALIZACIÓN CON BANDEJAS PORTA CABLES Y PERFIL C") -> CANALIZACIÓN CON BANDEJAS PORTA CABLES Y PERFIL C | J434: =IFERROR(__xludf.DUMMYFUNCTION("""COMPUTED_VALUE"""),"CANALIZACIÓN CON BANDEJAS PORTA CABLES Y PERFIL C") -> CANALIZACIÓN CON BANDEJAS PORTA CABLES Y PERFIL C | K434: =IFERROR(__xludf.DUMMYFUNCTION("""COMPUTED_VALUE"""),"CANALIZACIÓN CON BANDEJAS PORTA CABLES Y PERFIL C") -> CANALIZACIÓN CON BANDEJAS PORTA CABLES Y PERFIL C | L434: =IFERROR(__xludf.DUMMYFUNCTION("""COMPUTED_VALUE"""),"CANALIZACIÓN CON BANDEJAS PORTA CABLES Y PERFIL C") -> CANALIZACIÓN CON BANDEJAS PORTA CABLES Y PERFIL C | ... U434: =IFERROR(__xludf.DUMMYFUNCTION("""COMPUTED_VALUE"""),"CANALIZACIÓN CON BANDEJAS PORTA CABLES Y PERFIL C") -> CANALIZACIÓN CON BANDEJAS PORTA CABLES Y PERFIL C
E435: =IFERROR(__xludf.DUMMYFUNCTION("""COMPUTED_VALUE"""),"CABLEADOS EN CAÑERÍAS ") -> CABLEADOS EN CAÑERÍAS | F435: =IFERROR(__xludf.DUMMYFUNCTION("""COMPUTED_VALUE"""),"CABLEADOS EN CAÑERÍAS ") -> CABLEADOS EN CAÑERÍAS | G435: =IFERROR(__xludf.DUMMYFUNCTION("""COMPUTED_VALUE"""),"CABLEADOS EN CAÑERÍAS ") -> CABLEADOS EN CAÑERÍAS | H435: =IFERROR(__xludf.DUMMYFUNCTION("""COMPUTED_VALUE"""),"CABLEADOS EN CAÑERÍAS ") -> CABLEADOS EN CAÑERÍAS | I435: =IFERROR(__xludf.DUMMYFUNCTION("""COMPUTED_VALUE"""),"CABLEADOS EN CAÑERÍAS ") -> CABLEADOS EN CAÑERÍAS | J435: =IFERROR(__xludf.DUMMYFUNCTION("""COMPUTED_VALUE"""),"CABLEADOS EN CAÑERÍAS ") -> CABLEADOS EN CAÑERÍAS | K435: =IFERROR(__xludf.DUMMYFUNCTION("""COMPUTED_VALUE"""),"CABLEADOS EN CAÑERÍAS ") -> CABLEADOS EN CAÑERÍAS | L435: =IFERROR(__xludf.DUMMYFUNCTION("""COMPUTED_VALUE"""),"CABLEADOS EN CAÑERÍAS ") -> CABLEADOS EN CAÑERÍAS | ... U435: =IFERROR(__xludf.DUMMYFUNCTION("""COMPUTED_VALUE"""),"CABLEADOS EN CAÑERÍAS ") -> CABLEADOS EN CAÑERÍAS
E436: =IFERROR(__xludf.DUMMYFUNCTION("""COMPUTED_VALUE"""),"CABLEADO EN BANDEJAS PORTA CABLES ") -> CABLEADO EN BANDEJAS PORTA CABLES | F436: =IFERROR(__xludf.DUMMYFUNCTION("""COMPUTED_VALUE"""),"CABLEADO EN BANDEJAS PORTA CABLES ") -> CABLEADO EN BANDEJAS PORTA CABLES | G436: =IFERROR(__xludf.DUMMYFUNCTION("""COMPUTED_VALUE"""),"CABLEADO EN BANDEJAS PORTA CABLES ") -> CABLEADO EN BANDEJAS PORTA CABLES | H436: =IFERROR(__xludf.DUMMYFUNCTION("""COMPUTED_VALUE"""),"CABLEADO EN BANDEJAS PORTA CABLES ") -> CABLEADO EN BANDEJAS PORTA CABLES | I436: =IFERROR(__xludf.DUMMYFUNCTION("""COMPUTED_VALUE"""),"CABLEADO EN BANDEJAS PORTA CABLES ") -> CABLEADO EN BANDEJAS PORTA CABLES | J436: =IFERROR(__xludf.DUMMYFUNCTION("""COMPUTED_VALUE"""),"CABLEADO EN BANDEJAS PORTA CABLES ") -> CABLEADO EN BANDEJAS PORTA CABLES | K436: =IFERROR(__xludf.DUMMYFUNCTION("""COMPUTED_VALUE"""),"CABLEADO EN BANDEJAS PORTA CABLES ") -> CABLEADO EN BANDEJAS PORTA CABLES | L436: =IFERROR(__xludf.DUMMYFUNCTION("""COMPUTED_VALUE"""),"CABLEADO EN BANDEJAS PORTA CABLES ") -> CABLEADO EN BANDEJAS PORTA CABLES | ... U436: =IFERROR(__xludf.DUMMYFUNCTION("""COMPUTED_VALUE"""),"CABLEADO EN BANDEJAS PORTA CABLES ") -> CABLEADO EN BANDEJAS PORTA CABLES
E437: =IFERROR(__xludf.DUMMYFUNCTION("""COMPUTED_VALUE"""),"COLOCACIÓN DE INTERRUPTORES, TOMAS, ETC.") -> COLOCACIÓN DE INTERRUPTORES, TOMAS, ETC. | F437: =IFERROR(__xludf.DUMMYFUNCTION("""COMPUTED_VALUE"""),"COLOCACIÓN DE INTERRUPTORES, TOMAS, ETC.") -> COLOCACIÓN DE INTERRUPTORES, TOMAS, ETC. | G437: =IFERROR(__xludf.DUMMYFUNCTION("""COMPUTED_VALUE"""),"COLOCACIÓN DE INTERRUPTORES, TOMAS, ETC.") -> COLOCACIÓN DE INTERRUPTORES, TOMAS, ETC. | H437: =IFERROR(__xludf.DUMMYFUNCTION("""COMPUTED_VALUE"""),"COLOCACIÓN DE INTERRUPTORES, TOMAS, ETC.") -> COLOCACIÓN DE INTERRUPTORES, TOMAS, ETC. | I437: =IFERROR(__xludf.DUMMYFUNCTION("""COMPUTED_VALUE"""),"COLOCACIÓN DE INTERRUPTORES, TOMAS, ETC.") -> COLOCACIÓN DE INTERRUPTORES, TOMAS, ETC. | J437: =IFERROR(__xludf.DUMMYFUNCTION("""COMPUTED_VALUE"""),"COLOCACIÓN DE INTERRUPTORES, TOMAS, ETC.") -> COLOCACIÓN DE INTERRUPTORES, TOMAS, ETC. | K437: =IFERROR(__xludf.DUMMYFUNCTION("""COMPUTED_VALUE"""),"COLOCACIÓN DE INTERRUPTORES, TOMAS, ETC.") -> COLOCACIÓN DE INTERRUPTORES, TOMAS, ETC. | L437: =IFERROR(__xludf.DUMMYFUNCTION("""COMPUTED_VALUE"""),"COLOCACIÓN DE INTERRUPTORES, TOMAS, ETC.") -> COLOCACIÓN DE INTERRUPTORES, TOMAS, ETC. | ... U437: =IFERROR(__xludf.DUMMYFUNCTION("""COMPUTED_VALUE"""),"COLOCACIÓN DE INTERRUPTORES, TOMAS, ETC.") -> COLOCACIÓN DE INTERRUPTORES, TOMAS, ETC.
E438: =IFERROR(__xludf.DUMMYFUNCTION("""COMPUTED_VALUE"""),"COLOCACIÓN DE ARTEFACTOS") -> COLOCACIÓN DE ARTEFACTOS | F438: =IFERROR(__xludf.DUMMYFUNCTION("""COMPUTED_VALUE"""),"COLOCACIÓN DE ARTEFACTOS") -> COLOCACIÓN DE ARTEFACTOS | G438: =IFERROR(__xludf.DUMMYFUNCTION("""COMPUTED_VALUE"""),"COLOCACIÓN DE ARTEFACTOS") -> COLOCACIÓN DE ARTEFACTOS | H438: =IFERROR(__xludf.DUMMYFUNCTION("""COMPUTED_VALUE"""),"COLOCACIÓN DE ARTEFACTOS") -> COLOCACIÓN DE ARTEFACTOS | I438: =IFERROR(__xludf.DUMMYFUNCTION("""COMPUTED_VALUE"""),"COLOCACIÓN DE ARTEFACTOS") -> COLOCACIÓN DE ARTEFACTOS | J438: =IFERROR(__xludf.DUMMYFUNCTION("""COMPUTED_VALUE"""),"COLOCACIÓN DE ARTEFACTOS") -> COLOCACIÓN DE ARTEFACTOS | K438: =IFERROR(__xludf.DUMMYFUNCTION("""COMPUTED_VALUE"""),"COLOCACIÓN DE ARTEFACTOS") -> COLOCACIÓN DE ARTEFACTOS | L438: =IFERROR(__xludf.DUMMYFUNCTION("""COMPUTED_VALUE"""),"COLOCACIÓN DE ARTEFACTOS") -> COLOCACIÓN DE ARTEFACTOS | ... U438: =IFERROR(__xludf.DUMMYFUNCTION("""COMPUTED_VALUE"""),"COLOCACIÓN DE ARTEFACTOS") -> COLOCACIÓN DE ARTEFACTOS
E439: =IFERROR(__xludf.DUMMYFUNCTION("""COMPUTED_VALUE"""),"COLOCACIÓN DE ELEMENTOS DE PROTECCIÓN Y COMANDO") -> COLOCACIÓN DE ELEMENTOS DE PROTECCIÓN Y COMANDO | F439: =IFERROR(__xludf.DUMMYFUNCTION("""COMPUTED_VALUE"""),"COLOCACIÓN DE ELEMENTOS DE PROTECCIÓN Y COMANDO") -> COLOCACIÓN DE ELEMENTOS DE PROTECCIÓN Y COMANDO | G439: =IFERROR(__xludf.DUMMYFUNCTION("""COMPUTED_VALUE"""),"COLOCACIÓN DE ELEMENTOS DE PROTECCIÓN Y COMANDO") -> COLOCACIÓN DE ELEMENTOS DE PROTECCIÓN Y COMANDO | H439: =IFERROR(__xludf.DUMMYFUNCTION("""COMPUTED_VALUE"""),"COLOCACIÓN DE ELEMENTOS DE PROTECCIÓN Y COMANDO") -> COLOCACIÓN DE ELEMENTOS DE PROTECCIÓN Y COMANDO | I439: =IFERROR(__xludf.DUMMYFUNCTION("""COMPUTED_VALUE"""),"COLOCACIÓN DE ELEMENTOS DE PROTECCIÓN Y COMANDO") -> COLOCACIÓN DE ELEMENTOS DE PROTECCIÓN Y COMANDO | J439: =IFERROR(__xludf.DUMMYFUNCTION("""COMPUTED_VALUE"""),"COLOCACIÓN DE ELEMENTOS DE PROTECCIÓN Y COMANDO") -> COLOCACIÓN DE ELEMENTOS DE PROTECCIÓN Y COMANDO | K439: =IFERROR(__xludf.DUMMYFUNCTION("""COMPUTED_VALUE"""),"COLOCACIÓN DE ELEMENTOS DE PROTECCIÓN Y COMANDO") -> COLOCACIÓN DE ELEMENTOS DE PROTECCIÓN Y COMANDO | L439: =IFERROR(__xludf.DUMMYFUNCTION("""COMPUTED_VALUE"""),"COLOCACIÓN DE ELEMENTOS DE PROTECCIÓN Y COMANDO") -> COLOCACIÓN DE ELEMENTOS DE PROTECCIÓN Y COMANDO | ... U439: =IFERROR(__xludf.DUMMYFUNCTION("""COMPUTED_VALUE"""),"COLOCACIÓN DE ELEMENTOS DE PROTECCIÓN Y COMANDO") -> COLOCACIÓN DE ELEMENTOS DE PROTECCIÓN Y COMANDO
